<?xml version="1.0" ?>
<!-- =================================================================================== -->
<!-- |    This document was autogenerated by xacro from vmegarover.urdf.xacro          | -->
<!-- |    EDITING THIS FILE BY HAND IS NOT RECOMMENDED                                 | -->
<!-- =================================================================================== -->
<robot name="vmegarover">
  <!-- <xacro:include filename="$(find megarover_samples)/urdf/lrf/lrf.urdf.xacro"/> -->
  <!-- =============== Link & Joint =============== -->
  <!-- Base -->
  <link name="base_footprint"/>
  <joint name="base_link_joint" type="fixed">
    <origin xyz="0 0 0"/>
    <parent link="base_footprint"/>
    <child link="base_link"/>
  </joint>
  <link name="base_link">
    <visual>
      <geometry>
        <mesh filename="package://megarover_samples/meshes/dae/vmega_body.dae"/>
      </geometry>
    </visual>
    <collision>
      <geometry>
        <mesh filename="package://megarover_samples/meshes/stl/vmega_body.stl"/>
      </geometry>
    </collision>
    <inertial>
      <origin xyz="-0.061 0 -0.002"/>
      <mass value="13.754"/>
      <inertia ixx="0.110655982" ixy="0" ixz="0" iyy="0.20062619" iyz="0" izz="0.269504336"/>
    </inertial>
  </link>
  <joint name="right_wheel_joint" type="continuous">
    <origin xyz="0 -0.14199 0.074742"/>
    <parent link="base_link"/>
    <child link="right_wheel_link"/>
    <axis xyz="0 1 0"/>
  </joint>
  <link name="right_wheel_link">
    <visual>
      <geometry>
        <mesh filename="package://megarover_samples/meshes/dae/vmega_wheel.dae"/>
      </geometry>
    </visual>
    <collision>
      <origin rpy="-1.57079637 0 0" xyz="0 0 0"/>
      <geometry>
        <cylinder length="0.03" radius="0.076"/>
      </geometry>
    </collision>
    <inertial>
      <origin rpy="-1.57079637 0 0" xyz="0 0 0"/>
      <mass value="0.823"/>
      <inertia ixx="0.001250137" ixy="0" ixz="0" iyy="0.001250137" iyz="0" izz="0.0023768239999999996"/>
    </inertial>
  </link>
  <joint name="left_wheel_joint" type="continuous">
    <origin rpy="0 0 0" xyz="0 0.14199 0.074742"/>
    <parent link="base_link"/>
    <child link="left_wheel_link"/>
    <axis xyz="0 1 0"/>
  </joint>
  <link name="left_wheel_link">
    <visual>
      <geometry>
        <mesh filename="package://megarover_samples/meshes/dae/vmega_wheel.dae"/>
      </geometry>
      <origin xyz="0 0 0" rpy="0 0 3.14159265"/>
    </visual>
    <collision>
      <origin xyz="0 0 0" rpy="0 0 3.14159265"/>
      <geometry>
        <mesh filename="package://megarover_samples/meshes/dae/vmega_wheel.dae"/>
      </geometry>
    </collision>
    <inertial>
      <!-- <origin rpy="-1.57079637 0 0" xyz="0 0 0"/> -->
      <mass value="0.823"/>
      <inertia ixx="0.001250137" ixy="0" ixz="0" iyy="0.001250137" iyz="0" izz="0.0023768239999999996"/>
    </inertial>
  </link>
  <!-- Front LRF -->
  <!-- <xacro:lrf_v0 prefix="front" parent="base_link">
    <origin xyz="0.099 0 0.1015"/>
  </xacro:lrf_v0> -->
  <!-- Front LRF Upper-->
  <!-- <xacro:lrf_v0 prefix="front" parent="base_link">
    <origin xyz="0.099 0 0.2155"  rpy="${M_PI} 0 0" />
  </xacro:lrf_v0> -->
  <!-- Rear LRF -->
  <!-- xacro:lrf_v0 prefix="rear" parent="base_link">
    <origin xyz="-0.289 0 0.1015"  rpy="0 0 ${M_PI}" />
  </xacro:lrf_v0 -->
  <!-- LiDAR joint -->
  <joint name="LiDAR_joint" type="fixed">
    <!-- <parent link="base_footprint"/> -->
    <parent link="base_link"/>
    <child link="LiDAR"/>
    <origin xyz="0.099 0 0.1015"/>
  </joint>
  <!-- LiDAR link -->
  <link name="LiDAR">
    <visual>
      <geometry>
        <mesh filename="package://megarover_samples/meshes/dae/lrf.dae"/>
      </geometry>
    </visual>
    <collision>
      <geometry>
        <mesh filename="package://megarover_samples/meshes/stl/lrf.stl"/>
      </geometry>
    </collision>
    <inertial>
      <origin xyz="0 0 0"/>
      <mass value="0.218"/>
      <inertia ixx="9.083333333333335e-05" ixy="0" ixz="0" iyy="0.00013443333333333334" iyz="0" izz="0.00013443333333333334"/>
    </inertial>
  </link>
  <transmission name="right_wheel_trans">
    <type>transmission_interface/SimpleTransmission</type>
    <joint name="right_wheel_joint">
      <hardwareInterface>hardware_interface/VelocityJointInterface</hardwareInterface>
    </joint>
    <actuator name="right_wheel_motor">
      <hardwareInterface>hardware_interface/VelocityJointInterface</hardwareInterface>
      <mechanicalReduction>30</mechanicalReduction>
    </actuator>
  </transmission>
  <transmission name="left_wheel_trans">
    <type>transmission_interface/SimpleTransmission</type>
    <joint name="left_wheel_joint">
      <hardwareInterface>hardware_interface/VelocityJointInterface</hardwareInterface>
    </joint>
    <actuator name="left_wheel_motor">
      <hardwareInterface>hardware_interface/VelocityJointInterface</hardwareInterface>
      <mechanicalReduction>30</mechanicalReduction>
    </actuator>
  </transmission>
  <!-- =============== Gazebo =============== -->
  <gazebo>
    <plugin filename="libgazebo_ros_control.so" name="gazebo_ros_control">
      <robotNamespace>/vmegarover</robotNamespace>
    </plugin>
  </gazebo>
  <gazebo reference="base_link">
    <selfCollide>false</selfCollide>
    <mu1 value="0.0"/>
    <mu2 value="0.0"/>
  </gazebo>
  <gazebo reference="right_wheel_link">
    <selfCollide>false</selfCollide>
    <mu1 value="1.0"/>
    <mu2 value="1.0"/>
  </gazebo>
  <gazebo reference="left_wheel_link">
    <selfCollide>false</selfCollide>
    <mu1 value="1.0"/>
    <mu2 value="1.0"/>
  </gazebo>
  <!-- LRF -->
  <!-- <xacro:lrf_gazebo_v0 prefix="front"
                       min_rad="-1.57" max_rad="1.57"
                       min_range="0.06" max_range="4.0"/> -->
  <!-- xacro:lrf_gazebo_v0 prefix="rear"
                       min_rad="-1.57" max_rad="1.57"
                       min_range="0.06" max_range="4.0"/ -->
</robot>

